# 关于promise的异常捕获 #

## throw和catch ##

1. throw
   抛出异常之后会在后面的链式的失败方法中被捕获
2. catch
   + 标准的异常捕获方式，当前面使用了throw之后是无法catch的，推荐使用catch
   + catch((err) => {})后可继续链式调用
   + 在catch中的返回值是无法被下一个链式接收的
   *补充：链式调用中一个空then()无意义，直接跳过*
3. finally()
   结束链式调用的语句

# 并发得到异步操作的结果 #

## Promise.all() ##

```javascript
Promise.all([readFile('data/name.txt'), readFile('data/number.txt'), readFile('data/score.txt')]).then((val) => {
    console.log(val);
})
```
1. 参数是数组
2. 数组中放promise对象
3. 返回值也是promise对象
4. 当参数数组中的全部promise都执行完成之后就会根据执行结果触发到all后面相应的then函数,最后得到的结果(所有结果都在一个数组里面)可以作为下段链式调用的参数，该参数有两种结果：
    + 参数中的promise全部成功：得到的值是--并发得到**所有**异步操作完成后的结果
    + 参数中的promise存在失败: 得到的值是--**第一个**触发失败的promise的参数值

## Promise.race() ##

1. 参数是数组
2. 数组中放promise对象
3. 返回值也是promise对象
4. 参数中的promise不管状态是成功还是失败，谁先执行就返回谁的值